<?xml version="1.0" ?>
<sdf version="1.6">
  <model name="my_robot" canonical_link="chassis">


    <frame name="lidar_frame" attached_to="chassis">
      <pose>0 0 1 0 0 0</pose>
    </frame>

    <link name="chassis">
      <pose relative_to="__model__">0.5 0 0.4 0 0 0</pose>
      <inertial>
        <mass>1.14395</mass>
        <inertia>
          <ixx>0.126164</ixx>
          <ixy>0</ixy>
          <ixz>0</ixz>
          <iyy>0.416519</iyy>
          <iyz>0</iyz>
          <izz>0.481014</izz>
        </inertia>
      </inertial>
      <visual name="visual">
        <geometry>
          <box>
            <size>2.0 1.0 0.5</size>
          </box>
        </geometry>
        <material>
          <ambient>0.0 0.0 1.0 1</ambient>
          <diffuse>0.0 0.0 1.0 1</diffuse>
          <specular>0.0 0.0 1.0 1</specular>
        </material>
      </visual>
      <collision name="collision">
        <geometry>
          <box>
            <size>2.0 1.0 0.5</size>
          </box>
        </geometry>
      </collision>

    </link>
    <link name="cameras">
      <pose relative_to="chassis">0.8 0 1.5 0 0 0</pose>
      <inertial>
        <mass>0.1</mass>
        <inertia>
          <ixx>0.000166667</ixx>
          <ixy>0</ixy>
          <ixz>0</ixz>
          <iyy>0.000166667</iyy>
          <iyz>0</iyz>
          <izz>0.000166667</izz>
        </inertia>
      </inertial>
      <visual name="visual">
        <geometry>
          <box>
            <size>0.1 0.1 0.1</size>
          </box>
        </geometry>
      </visual>
      <collision name="collision">
        <geometry>
          <box>
            <size>0.01 0.01 0.01</size>
          </box>
        </geometry>
      </collision>
              <sensor name='camera' type='camera'>
          <camera>
            <horizontal_fov>1.0469999999999999</horizontal_fov>
            <image>
              <width>320</width>
              <height>240</height>
            </image>
            <clip>
              <near>0.10000000000000001</near>
              <far>100</far>
            </clip>
          </camera>
          <always_on>1</always_on>
          <update_rate>30</update_rate>
          <visualize>1</visualize>
          <topic>camera/image</topic>
        </sensor>
            <sensor name="thermal_camera_8bit" type="thermal">
  <camera>
    <horizontal_fov>1.047</horizontal_fov>
    <image>
      <width>320</width>
      <height>240</height>
      <format>L8</format>
    </image>
    <clip>
      <near>0.1</near>
      <far>100</far>
    </clip>
  </camera>
  <always_on>1</always_on>
  <update_rate>30</update_rate>
  <visualize>false</visualize>
  <topic>thermal_camera/image</topic>
  <plugin
    filename="ignition-gazebo-thermal-sensor-system"
    name="gz::sim::systems::ThermalSensor">
    <min_temp>253.15</min_temp>
    <max_temp>673.15</max_temp>
    <resolution>3.0</resolution>
  </plugin>
</sensor>
    </link>

    <link name="left_wheel">
      <pose relative_to="chassis">-0.5 0.6 0 -1.5707 0 0</pose>
      <inertial>
        <mass>2</mass>
        <inertia>
          <ixx>0.145833</ixx>
          <ixy>0</ixy>
          <ixz>0</ixz>
          <iyy>0.145833</iyy>
          <iyz>0</iyz>
          <izz>0.125</izz>
        </inertia>
      </inertial>
      <visual name="visual">
        <geometry>
          <cylinder>
            <radius>0.4</radius>
            <length>0.2</length>
          </cylinder>
        </geometry>
        <material>
          <ambient>1.0 0.0 0.0 1</ambient>
          <diffuse>1.0 0.0 0.0 1</diffuse>
          <specular>1.0 0.0 0.0 1</specular>
        </material>
      </visual>
      <collision name="collision">
        <geometry>
          <cylinder>
            <radius>0.4</radius>
            <length>0.2</length>
          </cylinder>
        </geometry>
      </collision>
    </link>

    <link name="right_wheel">
      <pose relative_to="chassis">-0.5 -0.6 0 -1.5707 0 0</pose>
      <inertial>
        <mass>1</mass>
        <inertia>
          <ixx>0.145833</ixx>
          <ixy>0</ixy>
          <ixz>0</ixz>
          <iyy>0.145833</iyy>
          <iyz>0</iyz>
          <izz>0.125</izz>
        </inertia>
      </inertial>
      <visual name="visual">
        <geometry>
          <cylinder>
            <radius>0.4</radius>
            <length>0.2</length>
          </cylinder>
        </geometry>
        <material>
          <ambient>1.0 0.0 0.0 1</ambient>
          <diffuse>1.0 0.0 0.0 1</diffuse>
          <specular>1.0 0.0 0.0 1</specular>
        </material>
      </visual>
      <collision name="collision">
        <geometry>
          <cylinder>
            <radius>0.4</radius>
            <length>0.2</length>
          </cylinder>
        </geometry>
      </collision>
    </link>

    <frame name="caster_frame" attached_to="chassis">
      <pose>0.8 0 -0.2 0 0 0</pose>
    </frame>

    <link name="caster">
      <pose relative_to="caster_frame"/>
      <inertial>
        <mass>1</mass>
        <inertia>
          <ixx>0.1</ixx>
          <ixy>0</ixy>
          <ixz>0</ixz>
          <iyy>0.1</iyy>
          <iyz>0</iyz>
          <izz>0.1</izz>
        </inertia>
      </inertial>
      <visual name="visual">
        <geometry>
          <sphere>
            <radius>0.2</radius>
          </sphere>
        </geometry>
        <material>
          <ambient>0.0 1 0.0 1</ambient>
          <diffuse>0.0 1 0.0 1</diffuse>
          <specular>0.0 1 0.0 1</specular>
        </material>
      </visual>
      <collision name="collision">
        <geometry>
          <sphere>
            <radius>0.2</radius>
          </sphere>
        </geometry>
      </collision>
    </link>

    <joint name="left_wheel_joint" type="revolute">
      <pose relative_to="left_wheel"/>
      <parent>chassis</parent>
      <child>left_wheel</child>
      <axis>
        <xyz expressed_in="__model__">0 1 0</xyz>
        <limit>
          <lower>-1.79769e+308</lower>
          <upper>1.79769e+308</upper>
        </limit>
      </axis>
    </joint>

    <joint name="right_wheel_joint" type="revolute">
      <pose relative_to="right_wheel"/>
      <parent>chassis</parent>
      <child>right_wheel</child>
      <axis>
        <xyz expressed_in="__model__">0 1 0</xyz>
        <limit>
          <lower>-1.79769e+308</lower>
          <upper>1.79769e+308</upper>
        </limit>
      </axis>
    </joint>

    <joint name="caster_wheel" type="ball">
      <parent>chassis</parent>
      <child>caster</child>
    </joint>

    <plugin
      filename="ignition-gazebo-diff-drive-system"
      name="ignition::gazebo::systems::DiffDrive">
      <left_joint>left_wheel_joint</left_joint>
      <right_joint>right_wheel_joint</right_joint>
      <wheel_separation>1.2</wheel_separation>
      <wheel_radius>0.4</wheel_radius>
      <odom_publish_frequency>50</odom_publish_frequency>
      <topic>cmd_vel</topic>
      <odom_topic>odom</odom_topic>
    </plugin>
  </model>
</sdf>
